[2022-07-29 22:25:29,625] {taskinstance.py:1179} INFO - Dependencies all met for <TaskInstance: dataperf.main manual__2022-07-29T22:25:25.074662+00:00 [queued]>
[2022-07-29 22:25:29,633] {taskinstance.py:1179} INFO - Dependencies all met for <TaskInstance: dataperf.main manual__2022-07-29T22:25:25.074662+00:00 [queued]>
[2022-07-29 22:25:29,633] {taskinstance.py:1376} INFO - 
--------------------------------------------------------------------------------
[2022-07-29 22:25:29,634] {taskinstance.py:1377} INFO - Starting attempt 1 of 1
[2022-07-29 22:25:29,634] {taskinstance.py:1378} INFO - 
--------------------------------------------------------------------------------
[2022-07-29 22:25:29,647] {taskinstance.py:1397} INFO - Executing <Task(BashOperator): main> on 2022-07-29 22:25:25.074662+00:00
[2022-07-29 22:25:29,650] {standard_task_runner.py:52} INFO - Started process 164 to run task
[2022-07-29 22:25:29,653] {standard_task_runner.py:79} INFO - Running: ['***', 'tasks', 'run', 'dataperf', 'main', 'manual__2022-07-29T22:25:25.074662+00:00', '--job-id', '224', '--raw', '--subdir', 'DAGS_FOLDER/dataperfr.py', '--cfg-path', '/tmp/tmpevfh2tkr', '--error-file', '/tmp/tmp32c680bx']
[2022-07-29 22:25:29,653] {standard_task_runner.py:80} INFO - Job 224: Subtask main
[2022-07-29 22:25:29,709] {task_command.py:371} INFO - Running <TaskInstance: dataperf.main manual__2022-07-29T22:25:25.074662+00:00 [running]> on host 5eb1407492fa
[2022-07-29 22:25:29,771] {taskinstance.py:1591} INFO - Exporting the following env vars:
AIRFLOW_CTX_DAG_OWNER=***
AIRFLOW_CTX_DAG_ID=dataperf
AIRFLOW_CTX_TASK_ID=main
AIRFLOW_CTX_EXECUTION_DATE=2022-07-29T22:25:25.074662+00:00
AIRFLOW_CTX_TRY_NUMBER=1
AIRFLOW_CTX_DAG_RUN_ID=manual__2022-07-29T22:25:25.074662+00:00
[2022-07-29 22:25:29,773] {subprocess.py:62} INFO - Tmp dir root location: 
 /tmp
[2022-07-29 22:25:29,774] {subprocess.py:74} INFO - Running command: ['bash', '-c', 'python /opt/***/dags/dependency/main.py']
[2022-07-29 22:25:29,782] {subprocess.py:85} INFO - Output:
[2022-07-29 22:25:31,958] {subprocess.py:92} INFO - Traceback (most recent call last):
[2022-07-29 22:25:31,958] {subprocess.py:92} INFO -   File "/opt/***/dags/dependency/main.py", line 103, in <module>
[2022-07-29 22:25:31,959] {subprocess.py:92} INFO -     run_correction_eval()
[2022-07-29 22:25:31,959] {subprocess.py:92} INFO -   File "/opt/***/dags/dependency/main.py", line 24, in run_correction_eval
[2022-07-29 22:25:31,959] {subprocess.py:92} INFO -     with open("task_setup.yml", "r") as f:
[2022-07-29 22:25:31,959] {subprocess.py:92} INFO - FileNotFoundError: [Errno 2] No such file or directory: 'task_setup.yml'
[2022-07-29 22:25:32,165] {subprocess.py:96} INFO - Command exited with return code 1
[2022-07-29 22:25:32,183] {taskinstance.py:1909} ERROR - Task failed with exception
Traceback (most recent call last):
  File "/home/airflow/.local/lib/python3.7/site-packages/airflow/operators/bash.py", line 195, in execute
    f'Bash command failed. The command returned a non-zero exit code {result.exit_code}.'
airflow.exceptions.AirflowException: Bash command failed. The command returned a non-zero exit code 1.
[2022-07-29 22:25:32,187] {taskinstance.py:1420} INFO - Marking task as FAILED. dag_id=dataperf, task_id=main, execution_date=20220729T222525, start_date=20220729T222529, end_date=20220729T222532
[2022-07-29 22:25:32,201] {standard_task_runner.py:97} ERROR - Failed to execute job 224 for task main (Bash command failed. The command returned a non-zero exit code 1.; 164)
[2022-07-29 22:25:32,233] {local_task_job.py:156} INFO - Task exited with return code 1
[2022-07-29 22:25:32,280] {local_task_job.py:273} INFO - 0 downstream tasks scheduled from follow-on schedule check
