[2022-07-29 20:47:16,680] {taskinstance.py:1179} INFO - Dependencies all met for <TaskInstance: dataperf.clone manual__2022-07-29T20:47:15.243546+00:00 [queued]>
[2022-07-29 20:47:16,692] {taskinstance.py:1179} INFO - Dependencies all met for <TaskInstance: dataperf.clone manual__2022-07-29T20:47:15.243546+00:00 [queued]>
[2022-07-29 20:47:16,692] {taskinstance.py:1376} INFO - 
--------------------------------------------------------------------------------
[2022-07-29 20:47:16,693] {taskinstance.py:1377} INFO - Starting attempt 1 of 1
[2022-07-29 20:47:16,693] {taskinstance.py:1378} INFO - 
--------------------------------------------------------------------------------
[2022-07-29 20:47:16,709] {taskinstance.py:1397} INFO - Executing <Task(BashOperator): clone> on 2022-07-29 20:47:15.243546+00:00
[2022-07-29 20:47:16,713] {standard_task_runner.py:52} INFO - Started process 82 to run task
[2022-07-29 20:47:16,716] {standard_task_runner.py:79} INFO - Running: ['***', 'tasks', 'run', 'dataperf', 'clone', 'manual__2022-07-29T20:47:15.243546+00:00', '--job-id', '206', '--raw', '--subdir', 'DAGS_FOLDER/dataperfr.py', '--cfg-path', '/tmp/tmpowuizud5', '--error-file', '/tmp/tmpc3es0j5t']
[2022-07-29 20:47:16,717] {standard_task_runner.py:80} INFO - Job 206: Subtask clone
[2022-07-29 20:47:16,784] {task_command.py:371} INFO - Running <TaskInstance: dataperf.clone manual__2022-07-29T20:47:15.243546+00:00 [running]> on host bd7d42b52bee
[2022-07-29 20:47:16,862] {taskinstance.py:1591} INFO - Exporting the following env vars:
AIRFLOW_CTX_DAG_OWNER=***
AIRFLOW_CTX_DAG_ID=dataperf
AIRFLOW_CTX_TASK_ID=clone
AIRFLOW_CTX_EXECUTION_DATE=2022-07-29T20:47:15.243546+00:00
AIRFLOW_CTX_TRY_NUMBER=1
AIRFLOW_CTX_DAG_RUN_ID=manual__2022-07-29T20:47:15.243546+00:00
[2022-07-29 20:47:16,864] {subprocess.py:62} INFO - Tmp dir root location: 
 /tmp
[2022-07-29 20:47:16,865] {subprocess.py:74} INFO - Running command: ['bash', '-c', 'git clone git@github.com:DS3Lab/dataperf-vision-debugging.git']
[2022-07-29 20:47:16,878] {subprocess.py:85} INFO - Output:
[2022-07-29 20:47:16,879] {subprocess.py:92} INFO - bash: line 1: git: command not found
[2022-07-29 20:47:16,880] {subprocess.py:96} INFO - Command exited with return code 127
[2022-07-29 20:47:16,895] {taskinstance.py:1909} ERROR - Task failed with exception
Traceback (most recent call last):
  File "/home/airflow/.local/lib/python3.7/site-packages/airflow/operators/bash.py", line 195, in execute
    f'Bash command failed. The command returned a non-zero exit code {result.exit_code}.'
airflow.exceptions.AirflowException: Bash command failed. The command returned a non-zero exit code 127.
[2022-07-29 20:47:16,900] {taskinstance.py:1420} INFO - Marking task as FAILED. dag_id=dataperf, task_id=clone, execution_date=20220729T204715, start_date=20220729T204716, end_date=20220729T204716
[2022-07-29 20:47:16,917] {standard_task_runner.py:97} ERROR - Failed to execute job 206 for task clone (Bash command failed. The command returned a non-zero exit code 127.; 82)
[2022-07-29 20:47:16,929] {local_task_job.py:156} INFO - Task exited with return code 1
[2022-07-29 20:47:17,063] {local_task_job.py:273} INFO - 0 downstream tasks scheduled from follow-on schedule check
